Workbook

Sheet PRODUTOS
A1: Código | B1: Produto | C1: Categoria | D1: Unidade | E1: Preço de custo | F1: Preço de venda | G1: Estoque mínimo
A2: P001 | B2: Arroz 5kg | C2: Alimentos | D2: Pacote | E2: 25 | F2: 32 | G2: 10
A3: P002 | B3: Feijão 1kg | C3: Alimentos | D3: Pacote | E3: 7 | F3: 10 | G3: 15
A4: P003 | B4: Óleo 900ml | C4: Alimentos | D4: Unidade | E4: 6 | F4: 9 | G4: 12

Sheet FORNECEDORES
A1: ID Fornecedor | B1: Nome | C1: Contato | D1: Telefone | E1: E-mail
A2: F001 | B2: Distribuidora Central | C2: Ana | D2: 61999990001 | E2: central@exemplo.com
A3: F002 | B3: Atacado Brasil | C3: João | D3: 61999990002 | E3: atacado@exemplo.com

Sheet ENTRADAS
A1: Data | B1: Código do produto | C1: Quantidade | D1: Custo unitário | E1: ID Fornecedor | F1: Nota fiscal | G1: Valor total
A2: 17/10/2026 | B2: P001 | C2: 20 | D2: 25 | E2: F001 | F2: NF001 | G2: =IF(OR(A2="",B2="",C2="",D2=""),"",C2*D2) -> 500
A3: 17/10/2026 | B3: P002 | C3: 30 | D3: 7 | E3: F002 | F3: NF002 | G3: =IF(OR(A3="",B3="",C3="",D3=""),"",C3*D3) -> 210
A4: 17/10/2026 | B4: P003 | C4: 20 | D4: 6 | E4: F001 | F4: NF003 | G4: =IF(OR(A4="",B4="",C4="",D4=""),"",C4*D4) -> 120
G5: =IF(OR(A5="",B5="",C5="",D5=""),"",C5*D5)
G6: =IF(OR(A6="",B6="",C6="",D6=""),"",C6*D6)
G7: =IF(OR(A7="",B7="",C7="",D7=""),"",C7*D7)
G8: =IF(OR(A8="",B8="",C8="",D8=""),"",C8*D8)
G9: =IF(OR(A9="",B9="",C9="",D9=""),"",C9*D9)
G10: =IF(OR(A10="",B10="",C10="",D10=""),"",C10*D10)
G11: =IF(OR(A11="",B11="",C11="",D11=""),"",C11*D11)
G12: =IF(OR(A12="",B12="",C12="",D12=""),"",C12*D12)
G13: =IF(OR(A13="",B13="",C13="",D13=""),"",C13*D13)
G14: =IF(OR(A14="",B14="",C14="",D14=""),"",C14*D14)
G15: =IF(OR(A15="",B15="",C15="",D15=""),"",C15*D15)
G16: =IF(OR(A16="",B16="",C16="",D16=""),"",C16*D16)
... G57: =IF(OR(A57="",B57="",C57="",D57=""),"",C57*D57)

Sheet SAÍDAS
A1: Data | B1: Código do produto | C1: Quantidade | D1: Tipo de saída | E1: Destino/Cliente | F1: Observação
A2: 17/10/2026 | B2: P001 | C2: 3 | D2: Venda | E2: Cliente 001 | F2: Teste de saída
A3: 17/10/2026 | B3: P002 | C3: 16 | D3: Venda | E3: Cliente 002 | F3: Teste de saída
A4: 17/10/2026 | B4: P003 | C4: 8 | D4: Perda | E4: Estoque | F4: Teste de perda

Sheet ESTOQUE
A1: Código | B1: Produto | C1: Categoria | D1: Unidade | E1: Total de entradas | F1: Total de saídas | G1: Saldo atual | H1: Estoque mínimo | I1: Status | J1: Preço de custo | K1: Valor em estoque
A2: =IF(PRODUTOS!A2="","",PRODUTOS!A2) -> P001 | B2: =IF(A2="","",IFERROR(VLOOKUP(A2,PRODUTOS!A:B,2,FALSE),"")) -> Arroz 5kg | C2: =IF(A2="","",IFERROR(VLOOKUP(A2,PRODUTOS!A:C,3,FALSE),"")) -> Alimentos | D2: =IF(A2="","",IFERROR(VLOOKUP(A2,PRODUTOS!A:D,4,FALSE),"")) -> Pacote | E2: =IF(A2="","",SUMIF(ENTRADAS!B:B,A2,ENTRADAS!C:C)) -> 20 | F2: =IF(A2="","",SUMIF('SAÍDAS'!B:B,A2,'SAÍDAS'!C:C)) -> 3 | G2: =IF(A2="","",E2-F2) -> 17 | H2: =IF(A2="","",IFERROR(VLOOKUP(A2,PRODUTOS!A:G,7,FALSE),"")) -> 10 | I2: =IF(OR(A2="",H2=""),"",IF(G2<=H2,"REPOR ESTOQUE","OK")) -> OK | J2: =IF(A2="","",IFERROR(VLOOKUP(A2,PRODUTOS!A:E,5,FALSE),"")) -> 25 | K2: =IF(OR(A2="",J2=""),"",G2*J2) -> 425
A3: =IF(PRODUTOS!A3="","",PRODUTOS!A3) -> P002 | B3: =IF(A3="","",IFERROR(VLOOKUP(A3,PRODUTOS!A:B,2,FALSE),"")) -> Feijão 1kg | C3: =IF(A3="","",IFERROR(VLOOKUP(A3,PRODUTOS!A:C,3,FALSE),"")) -> Alimentos | D3: =IF(A3="","",IFERROR(VLOOKUP(A3,PRODUTOS!A:D,4,FALSE),"")) -> Pacote | E3: =IF(A3="","",SUMIF(ENTRADAS!B:B,A3,ENTRADAS!C:C)) -> 30 | F3: =IF(A3="","",SUMIF('SAÍDAS'!B:B,A3,'SAÍDAS'!C:C)) -> 16 | G3: =IF(A3="","",E3-F3) -> 14 | H3: =IF(A3="","",IFERROR(VLOOKUP(A3,PRODUTOS!A:G,7,FALSE),"")) -> 15 | I3: =IF(OR(A3="",H3=""),"",IF(G3<=H3,"REPOR ESTOQUE","OK")) -> REPOR ESTOQUE | J3: =IF(A3="","",IFERROR(VLOOKUP(A3,PRODUTOS!A:E,5,FALSE),"")) -> 7 | K3: =IF(OR(A3="",J3=""),"",G3*J3) -> 98
A4: =IF(PRODUTOS!A4="","",PRODUTOS!A4) -> P003 | B4: =IF(A4="","",IFERROR(VLOOKUP(A4,PRODUTOS!A:B,2,FALSE),"")) -> Óleo 900ml | C4: =IF(A4="","",IFERROR(VLOOKUP(A4,PRODUTOS!A:C,3,FALSE),"")) -> Alimentos | D4: =IF(A4="","",IFERROR(VLOOKUP(A4,PRODUTOS!A:D,4,FALSE),"")) -> Unidade | E4: =IF(A4="","",SUMIF(ENTRADAS!B:B,A4,ENTRADAS!C:C)) -> 20 | F4: =IF(A4="","",SUMIF('SAÍDAS'!B:B,A4,'SAÍDAS'!C:C)) -> 8 | G4: =IF(A4="","",E4-F4) -> 12 | H4: =IF(A4="","",IFERROR(VLOOKUP(A4,PRODUTOS!A:G,7,FALSE),"")) -> 12 | I4: =IF(OR(A4="",H4=""),"",IF(G4<=H4,"REPOR ESTOQUE","OK")) -> REPOR ESTOQUE | J4: =IF(A4="","",IFERROR(VLOOKUP(A4,PRODUTOS!A:E,5,FALSE),"")) -> 6 | K4: =IF(OR(A4="",J4=""),"",G4*J4) -> 72
A5: =IF(PRODUTOS!A5="","",PRODUTOS!A5) | B5: =IF(A5="","",IFERROR(VLOOKUP(A5,PRODUTOS!A:B,2,FALSE),"")) | C5: =IF(A5="","",IFERROR(VLOOKUP(A5,PRODUTOS!A:C,3,FALSE),"")) | D5: =IF(A5="","",IFERROR(VLOOKUP(A5,PRODUTOS!A:D,4,FALSE),"")) | E5: =IF(A5="","",SUMIF(ENTRADAS!B:B,A5,ENTRADAS!C:C)) | F5: =IF(A5="","",SUMIF('SAÍDAS'!B:B,A5,'SAÍDAS'!C:C)) | G5: =IF(A5="","",E5-F5) | H5: =IF(A5="","",IFERROR(VLOOKUP(A5,PRODUTOS!A:G,7,FALSE),"")) | I5: =IF(OR(A5="",H5=""),"",IF(G5<=H5,"REPOR ESTOQUE","OK")) | J5: =IF(A5="","",IFERROR(VLOOKUP(A5,PRODUTOS!A:E,5,FALSE),"")) | K5: =IF(OR(A5="",J5=""),"",G5*J5)
A6: =IF(PRODUTOS!A6="","",PRODUTOS!A6) | B6: =IF(A6="","",IFERROR(VLOOKUP(A6,PRODUTOS!A:B,2,FALSE),"")) | C6: =IF(A6="","",IFERROR(VLOOKUP(A6,PRODUTOS!A:C,3,FALSE),"")) | D6: =IF(A6="","",IFERROR(VLOOKUP(A6,PRODUTOS!A:D,4,FALSE),"")) | E6: =IF(A6="","",SUMIF(ENTRADAS!B:B,A6,ENTRADAS!C:C)) | F6: =IF(A6="","",SUMIF('SAÍDAS'!B:B,A6,'SAÍDAS'!C:C)) | G6: =IF(A6="","",E6-F6) | H6: =IF(A6="","",IFERROR(VLOOKUP(A6,PRODUTOS!A:G,7,FALSE),"")) | I6: =IF(OR(A6="",H6=""),"",IF(G6<=H6,"REPOR ESTOQUE","OK")) | J6: =IF(A6="","",IFERROR(VLOOKUP(A6,PRODUTOS!A:E,5,FALSE),"")) | K6: =IF(OR(A6="",J6=""),"",G6*J6)
A7: =IF(PRODUTOS!A7="","",PRODUTOS!A7) | B7: =IF(A7="","",IFERROR(VLOOKUP(A7,PRODUTOS!A:B,2,FALSE),"")) | C7: =IF(A7="","",IFERROR(VLOOKUP(A7,PRODUTOS!A:C,3,FALSE),"")) | D7: =IF(A7="","",IFERROR(VLOOKUP(A7,PRODUTOS!A:D,4,FALSE),"")) | E7: =IF(A7="","",SUMIF(ENTRADAS!B:B,A7,ENTRADAS!C:C)) | F7: =IF(A7="","",SUMIF('SAÍDAS'!B:B,A7,'SAÍDAS'!C:C)) | G7: =IF(A7="","",E7-F7) | H7: =IF(A7="","",IFERROR(VLOOKUP(A7,PRODUTOS!A:G,7,FALSE),"")) | I7: =IF(OR(A7="",H7=""),"",IF(G7<=H7,"REPOR ESTOQUE","OK")) | J7: =IF(A7="","",IFERROR(VLOOKUP(A7,PRODUTOS!A:E,5,FALSE),"")) | K7: =IF(OR(A7="",J7=""),"",G7*J7)
A8: =IF(PRODUTOS!A8="","",PRODUTOS!A8) | B8: =IF(A8="","",IFERROR(VLOOKUP(A8,PRODUTOS!A:B,2,FALSE),"")) | C8: =IF(A8="","",IFERROR(VLOOKUP(A8,PRODUTOS!A:C,3,FALSE),"")) | D8: =IF(A8="","",IFERROR(VLOOKUP(A8,PRODUTOS!A:D,4,FALSE),"")) | E8: =IF(A8="","",SUMIF(ENTRADAS!B:B,A8,ENTRADAS!C:C)) | F8: =IF(A8="","",SUMIF('SAÍDAS'!B:B,A8,'SAÍDAS'!C:C)) | G8: =IF(A8="","",E8-F8) | H8: =IF(A8="","",IFERROR(VLOOKUP(A8,PRODUTOS!A:G,7,FALSE),"")) | I8: =IF(OR(A8="",H8=""),"",IF(G8<=H8,"REPOR ESTOQUE","OK")) | J8: =IF(A8="","",IFERROR(VLOOKUP(A8,PRODUTOS!A:E,5,FALSE),"")) | K8: =IF(OR(A8="",J8=""),"",G8*J8)
A9: =IF(PRODUTOS!A9="","",PRODUTOS!A9) | B9: =IF(A9="","",IFERROR(VLOOKUP(A9,PRODUTOS!A:B,2,FALSE),"")) | C9: =IF(A9="","",IFERROR(VLOOKUP(A9,PRODUTOS!A:C,3,FALSE),"")) | D9: =IF(A9="","",IFERROR(VLOOKUP(A9,PRODUTOS!A:D,4,FALSE),"")) | E9: =IF(A9="","",SUMIF(ENTRADAS!B:B,A9,ENTRADAS!C:C)) | F9: =IF(A9="","",SUMIF('SAÍDAS'!B:B,A9,'SAÍDAS'!C:C)) | G9: =IF(A9="","",E9-F9) | H9: =IF(A9="","",IFERROR(VLOOKUP(A9,PRODUTOS!A:G,7,FALSE),"")) | I9: =IF(OR(A9="",H9=""),"",IF(G9<=H9,"REPOR ESTOQUE","OK")) | J9: =IF(A9="","",IFERROR(VLOOKUP(A9,PRODUTOS!A:E,5,FALSE),"")) | K9: =IF(OR(A9="",J9=""),"",G9*J9)
A10: =IF(PRODUTOS!A10="","",PRODUTOS!A10) | B10: =IF(A10="","",IFERROR(VLOOKUP(A10,PRODUTOS!A:B,2,FALSE),"")) | C10: =IF(A10="","",IFERROR(VLOOKUP(A10,PRODUTOS!A:C,3,FALSE),"")) | D10: =IF(A10="","",IFERROR(VLOOKUP(A10,PRODUTOS!A:D,4,FALSE),"")) | E10: =IF(A10="","",SUMIF(ENTRADAS!B:B,A10,ENTRADAS!C:C)) | F10: =IF(A10="","",SUMIF('SAÍDAS'!B:B,A10,'SAÍDAS'!C:C)) | G10: =IF(A10="","",E10-F10) | H10: =IF(A10="","",IFERROR(VLOOKUP(A10,PRODUTOS!A:G,7,FALSE),"")) | I10: =IF(OR(A10="",H10=""),"",IF(G10<=H10,"REPOR ESTOQUE","OK")) | J10: =IF(A10="","",IFERROR(VLOOKUP(A10,PRODUTOS!A:E,5,FALSE),"")) | K10: =IF(OR(A10="",J10=""),"",G10*J10)
A11: =IF(PRODUTOS!A11="","",PRODUTOS!A11) | B11: =IF(A11="","",IFERROR(VLOOKUP(A11,PRODUTOS!A:B,2,FALSE),"")) | C11: =IF(A11="","",IFERROR(VLOOKUP(A11,PRODUTOS!A:C,3,FALSE),"")) | D11: =IF(A11="","",IFERROR(VLOOKUP(A11,PRODUTOS!A:D,4,FALSE),"")) | E11: =IF(A11="","",SUMIF(ENTRADAS!B:B,A11,ENTRADAS!C:C)) | F11: =IF(A11="","",SUMIF('SAÍDAS'!B:B,A11,'SAÍDAS'!C:C)) | G11: =IF(A11="","",E11-F11) | H11: =IF(A11="","",IFERROR(VLOOKUP(A11,PRODUTOS!A:G,7,FALSE),"")) | I11: =IF(OR(A11="",H11=""),"",IF(G11<=H11,"REPOR ESTOQUE","OK")) | J11: =IF(A11="","",IFERROR(VLOOKUP(A11,PRODUTOS!A:E,5,FALSE),"")) | K11: =IF(OR(A11="",J11=""),"",G11*J11)
A12: =IF(PRODUTOS!A12="","",PRODUTOS!A12) | B12: =IF(A12="","",IFERROR(VLOOKUP(A12,PRODUTOS!A:B,2,FALSE),"")) | C12: =IF(A12="","",IFERROR(VLOOKUP(A12,PRODUTOS!A:C,3,FALSE),"")) | D12: =IF(A12="","",IFERROR(VLOOKUP(A12,PRODUTOS!A:D,4,FALSE),"")) | E12: =IF(A12="","",SUMIF(ENTRADAS!B:B,A12,ENTRADAS!C:C)) | F12: =IF(A12="","",SUMIF('SAÍDAS'!B:B,A12,'SAÍDAS'!C:C)) | G12: =IF(A12="","",E12-F12) | H12: =IF(A12="","",IFERROR(VLOOKUP(A12,PRODUTOS!A:G,7,FALSE),"")) | I12: =IF(OR(A12="",H12=""),"",IF(G12<=H12,"REPOR ESTOQUE","OK")) | J12: =IF(A12="","",IFERROR(VLOOKUP(A12,PRODUTOS!A:E,5,FALSE),"")) | K12: =IF(OR(A12="",J12=""),"",G12*J12)
A13: =IF(PRODUTOS!A13="","",PRODUTOS!A13) | B13: =IF(A13="","",IFERROR(VLOOKUP(A13,PRODUTOS!A:B,2,FALSE),"")) | C13: =IF(A13="","",IFERROR(VLOOKUP(A13,PRODUTOS!A:C,3,FALSE),"")) | D13: =IF(A13="","",IFERROR(VLOOKUP(A13,PRODUTOS!A:D,4,FALSE),"")) | E13: =IF(A13="","",SUMIF(ENTRADAS!B:B,A13,ENTRADAS!C:C)) | F13: =IF(A13="","",SUMIF('SAÍDAS'!B:B,A13,'SAÍDAS'!C:C)) | G13: =IF(A13="","",E13-F13) | H13: =IF(A13="","",IFERROR(VLOOKUP(A13,PRODUTOS!A:G,7,FALSE),"")) | I13: =IF(OR(A13="",H13=""),"",IF(G13<=H13,"REPOR ESTOQUE","OK")) | J13: =IF(A13="","",IFERROR(VLOOKUP(A13,PRODUTOS!A:E,5,FALSE),"")) | K13: =IF(OR(A13="",J13=""),"",G13*J13)
... A22: =IF(PRODUTOS!A22="","",PRODUTOS!A22) | B22: =IF(A22="","",IFERROR(VLOOKUP(A22,PRODUTOS!A:B,2,FALSE),"")) | C22: =IF(A22="","",IFERROR(VLOOKUP(A22,PRODUTOS!A:C,3,FALSE),"")) | D22: =IF(A22="","",IFERROR(VLOOKUP(A22,PRODUTOS!A:D,4,FALSE),"")) | E22: =IF(A22="","",SUMIF(ENTRADAS!B:B,A22,ENTRADAS!C:C)) | F22: =IF(A22="","",SUMIF('SAÍDAS'!B:B,A22,'SAÍDAS'!C:C)) | G22: =IF(A22="","",E22-F22) | H22: =IF(A22="","",IFERROR(VLOOKUP(A22,PRODUTOS!A:G,7,FALSE),"")) | I22: =IF(OR(A22="",H22=""),"",IF(G22<=H22,"REPOR ESTOQUE","OK")) | J22: =IF(A22="","",IFERROR(VLOOKUP(A22,PRODUTOS!A:E,5,FALSE),"")) | K22: =IF(OR(A22="",J22=""),"",G22*J22)
A23: =IF(PRODUTOS!A23="","",PRODUTOS!A23) | B23: =IF(A23="","",IFERROR(VLOOKUP(A23,PRODUTOS!A:B,2,FALSE),"")) | C23: =IF(A23="","",IFERROR(VLOOKUP(A23,PRODUTOS!A:C,3,FALSE),"")) | E23: =IF(A23="","",SUMIF(ENTRADAS!B:B,A23,ENTRADAS!C:C)) | F23: =IF(A23="","",SUMIF('SAÍDAS'!B:B,A23,'SAÍDAS'!C:C)) | G23: =IF(A23="","",E23-F23) | H23: =IF(A23="","",IFERROR(VLOOKUP(A23,PRODUTOS!A:G,7,FALSE),"")) | I23: =IF(OR(A23="",H23=""),"",IF(G23<=H23,"REPOR ESTOQUE","OK")) | J23: =IF(A23="","",IFERROR(VLOOKUP(A23,PRODUTOS!A:E,5,FALSE),"")) | K23: =IF(OR(A23="",J23=""),"",G23*J23)
A24: =IF(PRODUTOS!A24="","",PRODUTOS!A24) | B24: =IF(A24="","",IFERROR(VLOOKUP(A24,PRODUTOS!A:B,2,FALSE),"")) | C24: =IF(A24="","",IFERROR(VLOOKUP(A24,PRODUTOS!A:C,3,FALSE),"")) | E24: =IF(A24="","",SUMIF(ENTRADAS!B:B,A24,ENTRADAS!C:C)) | F24: =IF(A24="","",SUMIF('SAÍDAS'!B:B,A24,'SAÍDAS'!C:C)) | G24: =IF(A24="","",E24-F24) | H24: =IF(A24="","",IFERROR(VLOOKUP(A24,PRODUTOS!A:G,7,FALSE),"")) | I24: =IF(OR(A24="",H24=""),"",IF(G24<=H24,"REPOR ESTOQUE","OK")) | J24: =IF(A24="","",IFERROR(VLOOKUP(A24,PRODUTOS!A:E,5,FALSE),"")) | K24: =IF(OR(A24="",J24=""),"",G24*J24)
A25: =IF(PRODUTOS!A25="","",PRODUTOS!A25) | B25: =IF(A25="","",IFERROR(VLOOKUP(A25,PRODUTOS!A:B,2,FALSE),"")) | C25: =IF(A25="","",IFERROR(VLOOKUP(A25,PRODUTOS!A:C,3,FALSE),"")) | E25: =IF(A25="","",SUMIF(ENTRADAS!B:B,A25,ENTRADAS!C:C)) | F25: =IF(A25="","",SUMIF('SAÍDAS'!B:B,A25,'SAÍDAS'!C:C)) | G25: =IF(A25="","",E25-F25) | H25: =IF(A25="","",IFERROR(VLOOKUP(A25,PRODUTOS!A:G,7,FALSE),"")) | I25: =IF(OR(A25="",H25=""),"",IF(G25<=H25,"REPOR ESTOQUE","OK")) | J25: =IF(A25="","",IFERROR(VLOOKUP(A25,PRODUTOS!A:E,5,FALSE),"")) | K25: =IF(OR(A25="",J25=""),"",G25*J25)
A26: =IF(PRODUTOS!A26="","",PRODUTOS!A26) | B26: =IF(A26="","",IFERROR(VLOOKUP(A26,PRODUTOS!A:B,2,FALSE),"")) | C26: =IF(A26="","",IFERROR(VLOOKUP(A26,PRODUTOS!A:C,3,FALSE),"")) | E26: =IF(A26="","",SUMIF(ENTRADAS!B:B,A26,ENTRADAS!C:C)) | F26: =IF(A26="","",SUMIF('SAÍDAS'!B:B,A26,'SAÍDAS'!C:C)) | G26: =IF(A26="","",E26-F26) | H26: =IF(A26="","",IFERROR(VLOOKUP(A26,PRODUTOS!A:G,7,FALSE),"")) | I26: =IF(OR(A26="",H26=""),"",IF(G26<=H26,"REPOR ESTOQUE","OK")) | J26: =IF(A26="","",IFERROR(VLOOKUP(A26,PRODUTOS!A:E,5,FALSE),"")) | K26: =IF(OR(A26="",J26=""),"",G26*J26)
A27: =IF(PRODUTOS!A27="","",PRODUTOS!A27) | B27: =IF(A27="","",IFERROR(VLOOKUP(A27,PRODUTOS!A:B,2,FALSE),"")) | C27: =IF(A27="","",IFERROR(VLOOKUP(A27,PRODUTOS!A:C,3,FALSE),"")) | E27: =IF(A27="","",SUMIF(ENTRADAS!B:B,A27,ENTRADAS!C:C)) | F27: =IF(A27="","",SUMIF('SAÍDAS'!B:B,A27,'SAÍDAS'!C:C)) | G27: =IF(A27="","",E27-F27) | H27: =IF(A27="","",IFERROR(VLOOKUP(A27,PRODUTOS!A:G,7,FALSE),"")) | I27: =IF(OR(A27="",H27=""),"",IF(G27<=H27,"REPOR ESTOQUE","OK")) | J27: =IF(A27="","",IFERROR(VLOOKUP(A27,PRODUTOS!A:E,5,FALSE),"")) | K27: =IF(OR(A27="",J27=""),"",G27*J27)
A28: =IF(PRODUTOS!A28="","",PRODUTOS!A28) | B28: =IF(A28="","",IFERROR(VLOOKUP(A28,PRODUTOS!A:B,2,FALSE),"")) | C28: =IF(A28="","",IFERROR(VLOOKUP(A28,PRODUTOS!A:C,3,FALSE),"")) | E28: =IF(A28="","",SUMIF(ENTRADAS!B:B,A28,ENTRADAS!C:C)) | F28: =IF(A28="","",SUMIF('SAÍDAS'!B:B,A28,'SAÍDAS'!C:C)) | G28: =IF(A28="","",E28-F28) | H28: =IF(A28="","",IFERROR(VLOOKUP(A28,PRODUTOS!A:G,7,FALSE),"")) | I28: =IF(OR(A28="",H28=""),"",IF(G28<=H28,"REPOR ESTOQUE","OK")) | J28: =IF(A28="","",IFERROR(VLOOKUP(A28,PRODUTOS!A:E,5,FALSE),"")) | K28: =IF(OR(A28="",J28=""),"",G28*J28)
A29: =IF(PRODUTOS!A29="","",PRODUTOS!A29) | B29: =IF(A29="","",IFERROR(VLOOKUP(A29,PRODUTOS!A:B,2,FALSE),"")) | C29: =IF(A29="","",IFERROR(VLOOKUP(A29,PRODUTOS!A:C,3,FALSE),"")) | E29: =IF(A29="","",SUMIF(ENTRADAS!B:B,A29,ENTRADAS!C:C)) | F29: =IF(A29="","",SUMIF('SAÍDAS'!B:B,A29,'SAÍDAS'!C:C)) | G29: =IF(A29="","",E29-F29) | H29: =IF(A29="","",IFERROR(VLOOKUP(A29,PRODUTOS!A:G,7,FALSE),"")) | I29: =IF(OR(A29="",H29=""),"",IF(G29<=H29,"REPOR ESTOQUE","OK")) | J29: =IF(A29="","",IFERROR(VLOOKUP(A29,PRODUTOS!A:E,5,FALSE),"")) | K29: =IF(OR(A29="",J29=""),"",G29*J29)
A30: =IF(PRODUTOS!A30="","",PRODUTOS!A30) | B30: =IF(A30="","",IFERROR(VLOOKUP(A30,PRODUTOS!A:B,2,FALSE),"")) | C30: =IF(A30="","",IFERROR(VLOOKUP(A30,PRODUTOS!A:C,3,FALSE),"")) | E30: =IF(A30="","",SUMIF(ENTRADAS!B:B,A30,ENTRADAS!C:C)) | F30: =IF(A30="","",SUMIF('SAÍDAS'!B:B,A30,'SAÍDAS'!C:C)) | G30: =IF(A30="","",E30-F30) | H30: =IF(A30="","",IFERROR(VLOOKUP(A30,PRODUTOS!A:G,7,FALSE),"")) | I30: =IF(OR(A30="",H30=""),"",IF(G30<=H30,"REPOR ESTOQUE","OK")) | J30: =IF(A30="","",IFERROR(VLOOKUP(A30,PRODUTOS!A:E,5,FALSE),"")) | K30: =IF(OR(A30="",J30=""),"",G30*J30)
A31: =IF(PRODUTOS!A31="","",PRODUTOS!A31) | B31: =IF(A31="","",IFERROR(VLOOKUP(A31,PRODUTOS!A:B,2,FALSE),"")) | C31: =IF(A31="","",IFERROR(VLOOKUP(A31,PRODUTOS!A:C,3,FALSE),"")) | E31: =IF(A31="","",SUMIF(ENTRADAS!B:B,A31,ENTRADAS!C:C)) | F31: =IF(A31="","",SUMIF('SAÍDAS'!B:B,A31,'SAÍDAS'!C:C)) | G31: =IF(A31="","",E31-F31) | I31: =IF(OR(A31="",H31=""),"",IF(G31<=H31,"REPOR ESTOQUE","OK")) | J31: =IF(A31="","",IFERROR(VLOOKUP(A31,PRODUTOS!A:E,5,FALSE),"")) | K31: =IF(OR(A31="",J31=""),"",G31*J31)
A32: =IF(PRODUTOS!A32="","",PRODUTOS!A32) | B32: =IF(A32="","",IFERROR(VLOOKUP(A32,PRODUTOS!A:B,2,FALSE),"")) | C32: =IF(A32="","",IFERROR(VLOOKUP(A32,PRODUTOS!A:C,3,FALSE),"")) | E32: =IF(A32="","",SUMIF(ENTRADAS!B:B,A32,ENTRADAS!C:C)) | F32: =IF(A32="","",SUMIF('SAÍDAS'!B:B,A32,'SAÍDAS'!C:C)) | G32: =IF(A32="","",E32-F32) | I32: =IF(OR(A32="",H32=""),"",IF(G32<=H32,"REPOR ESTOQUE","OK")) | J32: =IF(A32="","",IFERROR(VLOOKUP(A32,PRODUTOS!A:E,5,FALSE),"")) | K32: =IF(OR(A32="",J32=""),"",G32*J32)
A33: =IF(PRODUTOS!A33="","",PRODUTOS!A33) | B33: =IF(A33="","",IFERROR(VLOOKUP(A33,PRODUTOS!A:B,2,FALSE),"")) | C33: =IF(A33="","",IFERROR(VLOOKUP(A33,PRODUTOS!A:C,3,FALSE),"")) | E33: =IF(A33="","",SUMIF(ENTRADAS!B:B,A33,ENTRADAS!C:C)) | F33: =IF(A33="","",SUMIF('SAÍDAS'!B:B,A33,'SAÍDAS'!C:C)) | G33: =IF(A33="","",E33-F33) | I33: =IF(OR(A33="",H33=""),"",IF(G33<=H33,"REPOR ESTOQUE","OK")) | J33: =IF(A33="","",IFERROR(VLOOKUP(A33,PRODUTOS!A:E,5,FALSE),"")) | K33: =IF(OR(A33="",J33=""),"",G33*J33)
A34: =IF(PRODUTOS!A34="","",PRODUTOS!A34) | B34: =IF(A34="","",IFERROR(VLOOKUP(A34,PRODUTOS!A:B,2,FALSE),"")) | C34: =IF(A34="","",IFERROR(VLOOKUP(A34,PRODUTOS!A:C,3,FALSE),"")) | F34: =IF(A34="","",SUMIF('SAÍDAS'!B:B,A34,'SAÍDAS'!C:C)) | G34: =IF(A34="","",E34-F34) | I34: =IF(OR(A34="",H34=""),"",IF(G34<=H34,"REPOR ESTOQUE","OK")) | J34: =IF(A34="","",IFERROR(VLOOKUP(A34,PRODUTOS!A:E,5,FALSE),"")) | K34: =IF(OR(A34="",J34=""),"",G34*J34)
B35: =IF(A35="","",IFERROR(VLOOKUP(A35,PRODUTOS!A:B,2,FALSE),"")) | C35: =IF(A35="","",IFERROR(VLOOKUP(A35,PRODUTOS!A:C,3,FALSE),"")) | F35: =IF(A35="","",SUMIF('SAÍDAS'!B:B,A35,'SAÍDAS'!C:C)) | G35: =IF(A35="","",E35-F35) | I35: =IF(OR(A35="",H35=""),"",IF(G35<=H35,"REPOR ESTOQUE","OK")) | J35: =IF(A35="","",IFERROR(VLOOKUP(A35,PRODUTOS!A:E,5,FALSE),"")) | K35: =IF(OR(A35="",J35=""),"",G35*J35)
B36: =IF(A36="","",IFERROR(VLOOKUP(A36,PRODUTOS!A:B,2,FALSE),"")) | C36: =IF(A36="","",IFERROR(VLOOKUP(A36,PRODUTOS!A:C,3,FALSE),"")) | F36: =IF(A36="","",SUMIF('SAÍDAS'!B:B,A36,'SAÍDAS'!C:C)) | G36: =IF(A36="","",E36-F36) | I36: =IF(OR(A36="",H36=""),"",IF(G36<=H36,"REPOR ESTOQUE","OK")) | J36: =IF(A36="","",IFERROR(VLOOKUP(A36,PRODUTOS!A:E,5,FALSE),"")) | K36: =IF(OR(A36="",J36=""),"",G36*J36)
B37: =IF(A37="","",IFERROR(VLOOKUP(A37,PRODUTOS!A:B,2,FALSE),"")) | C37: =IF(A37="","",IFERROR(VLOOKUP(A37,PRODUTOS!A:C,3,FALSE),"")) | F37: =IF(A37="","",SUMIF('SAÍDAS'!B:B,A37,'SAÍDAS'!C:C)) | G37: =IF(A37="","",E37-F37) | I37: =IF(OR(A37="",H37=""),"",IF(G37<=H37,"REPOR ESTOQUE","OK")) | J37: =IF(A37="","",IFERROR(VLOOKUP(A37,PRODUTOS!A:E,5,FALSE),"")) | K37: =IF(OR(A37="",J37=""),"",G37*J37)
B38: =IF(A38="","",IFERROR(VLOOKUP(A38,PRODUTOS!A:B,2,FALSE),"")) | C38: =IF(A38="","",IFERROR(VLOOKUP(A38,PRODUTOS!A:C,3,FALSE),"")) | F38: =IF(A38="","",SUMIF('SAÍDAS'!B:B,A38,'SAÍDAS'!C:C)) | G38: =IF(A38="","",E38-F38) | I38: =IF(OR(A38="",H38=""),"",IF(G38<=H38,"REPOR ESTOQUE","OK")) | J38: =IF(A38="","",IFERROR(VLOOKUP(A38,PRODUTOS!A:E,5,FALSE),"")) | K38: =IF(OR(A38="",J38=""),"",G38*J38)
B39: =IF(A39="","",IFERROR(VLOOKUP(A39,PRODUTOS!A:B,2,FALSE),"")) | C39: =IF(A39="","",IFERROR(VLOOKUP(A39,PRODUTOS!A:C,3,FALSE),"")) | F39: =IF(A39="","",SUMIF('SAÍDAS'!B:B,A39,'SAÍDAS'!C:C)) | G39: =IF(A39="","",E39-F39) | I39: =IF(OR(A39="",H39=""),"",IF(G39<=H39,"REPOR ESTOQUE","OK")) | J39: =IF(A39="","",IFERROR(VLOOKUP(A39,PRODUTOS!A:E,5,FALSE),"")) | K39: =IF(OR(A39="",J39=""),"",G39*J39)
B40: =IF(A40="","",IFERROR(VLOOKUP(A40,PRODUTOS!A:B,2,FALSE),"")) | C40: =IF(A40="","",IFERROR(VLOOKUP(A40,PRODUTOS!A:C,3,FALSE),"")) | F40: =IF(A40="","",SUMIF('SAÍDAS'!B:B,A40,'SAÍDAS'!C:C)) | I40: =IF(OR(A40="",H40=""),"",IF(G40<=H40,"REPOR ESTOQUE","OK")) | J40: =IF(A40="","",IFERROR(VLOOKUP(A40,PRODUTOS!A:E,5,FALSE),"")) | K40: =IF(OR(A40="",J40=""),"",G40*J40)
B41: =IF(A41="","",IFERROR(VLOOKUP(A41,PRODUTOS!A:B,2,FALSE),"")) | C41: =IF(A41="","",IFERROR(VLOOKUP(A41,PRODUTOS!A:C,3,FALSE),"")) | F41: =IF(A41="","",SUMIF('SAÍDAS'!B:B,A41,'SAÍDAS'!C:C)) | I41: =IF(OR(A41="",H41=""),"",IF(G41<=H41,"REPOR ESTOQUE","OK")) | J41: =IF(A41="","",IFERROR(VLOOKUP(A41,PRODUTOS!A:E,5,FALSE),"")) | K41: =IF(OR(A41="",J41=""),"",G41*J41)
B42: =IF(A42="","",IFERROR(VLOOKUP(A42,PRODUTOS!A:B,2,FALSE),"")) | C42: =IF(A42="","",IFERROR(VLOOKUP(A42,PRODUTOS!A:C,3,FALSE),"")) | F42: =IF(A42="","",SUMIF('SAÍDAS'!B:B,A42,'SAÍDAS'!C:C)) | I42: =IF(OR(A42="",H42=""),"",IF(G42<=H42,"REPOR ESTOQUE","OK")) | J42: =IF(A42="","",IFERROR(VLOOKUP(A42,PRODUTOS!A:E,5,FALSE),"")) | K42: =IF(OR(A42="",J42=""),"",G42*J42)
B43: =IF(A43="","",IFERROR(VLOOKUP(A43,PRODUTOS!A:B,2,FALSE),"")) | C43: =IF(A43="","",IFERROR(VLOOKUP(A43,PRODUTOS!A:C,3,FALSE),"")) | I43: =IF(OR(A43="",H43=""),"",IF(G43<=H43,"REPOR ESTOQUE","OK")) | J43: =IF(A43="","",IFERROR(VLOOKUP(A43,PRODUTOS!A:E,5,FALSE),""))
B44: =IF(A44="","",IFERROR(VLOOKUP(A44,PRODUTOS!A:B,2,FALSE),"")) | C44: =IF(A44="","",IFERROR(VLOOKUP(A44,PRODUTOS!A:C,3,FALSE),"")) | I44: =IF(OR(A44="",H44=""),"",IF(G44<=H44,"REPOR ESTOQUE","OK")) | J44: =IF(A44="","",IFERROR(VLOOKUP(A44,PRODUTOS!A:E,5,FALSE),""))
B45: =IF(A45="","",IFERROR(VLOOKUP(A45,PRODUTOS!A:B,2,FALSE),"")) | C45: =IF(A45="","",IFERROR(VLOOKUP(A45,PRODUTOS!A:C,3,FALSE),"")) | I45: =IF(OR(A45="",H45=""),"",IF(G45<=H45,"REPOR ESTOQUE","OK")) | J45: =IF(A45="","",IFERROR(VLOOKUP(A45,PRODUTOS!A:E,5,FALSE),""))
B46: =IF(A46="","",IFERROR(VLOOKUP(A46,PRODUTOS!A:B,2,FALSE),"")) | C46: =IF(A46="","",IFERROR(VLOOKUP(A46,PRODUTOS!A:C,3,FALSE),"")) | I46: =IF(OR(A46="",H46=""),"",IF(G46<=H46,"REPOR ESTOQUE","OK"))
C47: =IF(A47="","",IFERROR(VLOOKUP(A47,PRODUTOS!A:C,3,FALSE),"")) | I47: =IF(OR(A47="",H47=""),"",IF(G47<=H47,"REPOR ESTOQUE","OK"))
C48: =IF(A48="","",IFERROR(VLOOKUP(A48,PRODUTOS!A:C,3,FALSE),"")) | I48: =IF(OR(A48="",H48=""),"",IF(G48<=H48,"REPOR ESTOQUE","OK"))
...

Sheet DASHBOARD
A1: SISTEMA DE GESTÃO DE ESTOQUE | F1: Produto | G1: Valor em estoque
F2: Arroz 5kg | G2: =ESTOQUE!K2 -> 425
A3: PRODUTOS CADASTRADOS | B3: =COUNTA(PRODUTOS!A2:A999) -> 3 | F3: Feijão 1kg | G3: =ESTOQUE!K3 -> 98
F4: Óleo 900ml | G4: =ESTOQUE!K4 -> 72
A5: PRODUTOS PARA REPOSIÇÃO | B5: =COUNTIF(ESTOQUE!I2:I999,"REPOR ESTOQUE") -> 2
A7: VALOR DO ESTOQUE | B7: =SUM(ESTOQUE!K2:K999) -> 595
A9: TOTAL DE ENTRADAS | B9: =SUM(ENTRADAS!G2:G999) -> 830
A13: Status | B13: Quantidade
A14: OK | B14: =COUNTIF(ESTOQUE!I2:I999,"OK") -> 1
A15: REPOR ESTOQUE | B15: =COUNTIF(ESTOQUE!I2:I999,"REPOR ESTOQUE") -> 2
